<?xml version="1.0" encoding="UTF-8"?>
<!-- DO NOT EDIT: Generated from standard_vtol.sdf.jinja -->
<sdf version='1.5'>
  <model name='tiltrotor'>
    <pose>0 0 0.246 0 0 0</pose>
    <link name='base_link'>
      <pose>0 0 0 0 0 0</pose>
      <inertial>
        <pose>0 0 0 0 0 0</pose>
        <mass>2.9</mass>
        <inertia>
          <ixx>0.197563</ixx>
          <ixy>0</ixy>
          <ixz>0</ixz>
          <iyy>0.1458929</iyy>
          <iyz>0</iyz>
          <izz>0.1477</izz>
        </inertia>
      </inertial>
      <collision name='base_link_collision'>
        <pose>-0.01 0 -0.08 0 0 0</pose>
        <geometry>
          <box>
            <size>0.55 2.144 0.05</size>
          </box>
        </geometry>
        <surface>
          <contact>
            <ode>
              <kp>100000</kp>
              <kd>1.0</kd>
              <max_vel>0.1</max_vel>
              <min_depth>0.001</min_depth>
            </ode>
          </contact>
          <friction>
            <ode/>
          </friction>
        </surface>
      </collision>
      <visual name='base_link_visual'>
        <pose>-1.1 -0.63 -0.1 1.5707963268 0 1.5707963268</pose> <!-- first 前后  second 左右  third 上下 -->
        <geometry>
          <mesh>
            <scale>0.002 0.002 0.002</scale>
            <uri>model://tiltrotor/M3.dae</uri>
          </mesh>
        </geometry>
        <material> <!-- DarkGrey-->
          <ambient>0.175 0.175 0.175 1.0</ambient>
          <diffuse>0.175 0.175 0.175 1.0</diffuse>
        </material>
      </visual>



      <gravity>1</gravity>
      <enable_wind>true</enable_wind>
      <velocity_decay/>
      <self_collide>0</self_collide>

      <sensor name="imu_sensor" type="imu">
        <always_on>1</always_on>
        <update_rate>250</update_rate>
        <imu>
          <angular_velocity>
            <x>
              <noise type="gaussian">
                <mean>0</mean>
                <stddev>0.0003394</stddev>
                <dynamic_bias_stddev>3.8785e-05</dynamic_bias_stddev>
                <dynamic_bias_correlation_time>1000</dynamic_bias_correlation_time>
              </noise>
            </x>
            <y>
              <noise type="gaussian">
                <mean>0</mean>
                <stddev>0.0003394</stddev>
                <dynamic_bias_stddev>3.8785e-05</dynamic_bias_stddev>
                <dynamic_bias_correlation_time>1000</dynamic_bias_correlation_time>
              </noise>
            </y>
            <z>
              <noise type="gaussian">
                <mean>0</mean>
                <stddev>0.0003394</stddev>
                <dynamic_bias_stddev>3.8785e-05</dynamic_bias_stddev>
                <dynamic_bias_correlation_time>1000</dynamic_bias_correlation_time>
              </noise>
            </z>
          </angular_velocity>
          <linear_acceleration>
            <x>
              <noise type="gaussian">
                <mean>0</mean>
                <stddev>0.004</stddev>
                <dynamic_bias_stddev>0.006</dynamic_bias_stddev>
                <dynamic_bias_correlation_time>300</dynamic_bias_correlation_time>
              </noise>
            </x>
            <y>
              <noise type="gaussian">
                <mean>0</mean>
                <stddev>0.004</stddev>
                <dynamic_bias_stddev>0.006</dynamic_bias_stddev>
                <dynamic_bias_correlation_time>300</dynamic_bias_correlation_time>
              </noise>
            </y>
            <z>
              <noise type="gaussian">
                <mean>0</mean>
                <stddev>0.004</stddev>
                <dynamic_bias_stddev>0.006</dynamic_bias_stddev>
                <dynamic_bias_correlation_time>300</dynamic_bias_correlation_time>
              </noise>
            </z>
          </linear_acceleration>
        </imu>
      </sensor>
      <sensor name="air_pressure_sensor" type="air_pressure">
        <always_on>1</always_on>
        <update_rate>50</update_rate>
        <air_pressure>
          <pressure>
            <noise type="gaussian">
              <mean>0</mean>
              <stddev>0.01</stddev>
            </noise>
          </pressure>
        </air_pressure>
      </sensor>
      <sensor name="magnetometer_sensor" type="magnetometer">
        <always_on>1</always_on>
        <update_rate>100</update_rate>
        <magnetometer>
          <!-- TODO: update to fix units and coordinate system when we move past Harmonic -->
          <!-- See https://github.com/gazebosim/gz-sim/pull/2460 -->
          <!-- 3mgauss RMS: NOTE: noise is in tesla but sensor reports data in gauss -->
          <!-- Noise modeled after IIS2MDC -->
          <x>
            <noise type="gaussian">
              <stddev>0.0001</stddev>
            </noise>
          </x>
          <y>
            <noise type="gaussian">
              <stddev>0.0001</stddev>
            </noise>
          </y>
          <z>
            <noise type="gaussian">
              <stddev>0.0001</stddev>
            </noise>
          </z>
        </magnetometer>
      </sensor>
      <sensor name="navsat_sensor" type="navsat">
        <always_on>1</always_on>
        <update_rate>30</update_rate>
      </sensor>
    </link>

    <include merge="true">
      <uri>model://airspeed</uri>
      <pose >0. 0. 0. 0. 0. 0.</pose>
    </include>
    <joint name='airspeed_joint' type='fixed'>
      <parent>base_link</parent>
      <child>airspeed_link</child>
      <pose relative_to="base_link">-0 0 0 0 0 0</pose>
    </joint>

    <link name='motor_0'>
      <pose>0.35 0.42 0.300 0 0 0</pose>  <!-- 0.025 upper is rotor_0, left front -->
      <inertial>
        <pose>0 0 0 0 0 0</pose>
        <mass>0.05</mass>
        <inertia>
          <ixx>0.0166704</ixx>
          <ixy>0</ixy>
          <ixz>0</ixz>
          <iyy>0.0166704</iyy>
          <iyz>0</iyz>
          <izz>0.0167604</izz>
        </inertia>
      </inertial>
      <collision name='motor_0_collision'>
        <pose>0 0 0 0 0 0</pose>
        <geometry>
          <cylinder>
            <length>0.035</length>
            <radius>0.02</radius>
          </cylinder>
        </geometry>
        <surface>
          <contact>
            <ode/>
          </contact>
          <friction>
            <ode/>
          </friction>
        </surface>
      </collision>
      <visual name='motor_0_visual'>
        <pose>0 0 0 0 0 0</pose>
        <geometry>
          <cylinder>
            <length>0.035</length>
            <radius>0.02</radius>
          </cylinder>
        </geometry>
        <material>
          <ambient>0.175 0.175 0.175 1.0</ambient>
          <diffuse>0.175 0.175 0.175 1.0</diffuse>
        </material>
      </visual>
      <gravity>1</gravity>
      <velocity_decay/>
      <self_collide>0</self_collide>
    </link>

    <joint name='motor_0_joint' type='revolute'>
      <child>motor_0</child>
      <parent>base_link</parent>
      <axis>
        <xyz>0 1 0</xyz>
        <limit>
          <lower>-0.785</lower>
          <upper>0.785</upper>
        </limit>
        <dynamics>
          <friction>1.0</friction>
          <spring_reference>0</spring_reference>
          <spring_stiffness>0</spring_stiffness>
        </dynamics>
        <use_parent_model_frame>1</use_parent_model_frame>
      </axis>
    </joint>

    <link name='rotor_0'>
      <pose>0.35 0.42 0.325 0 0 0</pose>
      <inertial>
        <pose>0 0 0 0 0 0</pose>
        <mass>0.005</mass>
        <inertia>
          <ixx>9.75e-07</ixx>
          <ixy>0</ixy>
          <ixz>0</ixz>
          <iyy>0.000166704</iyy>
          <iyz>0</iyz>
          <izz>0.000167604</izz>
        </inertia>
      </inertial>
      <collision name='rotor_0_collision'>
        <pose>0 0 0 0 0 0</pose>
        <geometry>
          <cylinder>
            <length>0.005</length>
            <radius>0.1</radius>
          </cylinder>
        </geometry>
        <surface>
          <contact>
            <ode/>
          </contact>
          <friction>
            <ode/>
          </friction>
        </surface>
      </collision>
      <visual name='rotor_0_visual'>
        <pose>0 0 0 0 0 0</pose>
        <geometry>
          <mesh>
            <scale>1 1 1</scale>
            <uri>model://standard_vtol/meshes/iris_prop_ccw.dae</uri>
          </mesh>
        </geometry>
        <material>  <!-- Blue -->
          <ambient>0 0 1 1.0</ambient>
          <diffuse>0 0 1 1.0</diffuse>
        </material>
      </visual>
      <gravity>1</gravity>
      <velocity_decay/>
      <self_collide>0</self_collide>
    </link>
    <joint name='rotor_0_joint' type='revolute'>
      <child>rotor_0</child>
      <parent>motor_0</parent>
      <axis>
        <xyz>0 0 1</xyz>
        <limit>
          <lower>-1e+16</lower>
          <upper>1e+16</upper>
        </limit>
        <dynamics>
          <spring_reference>0</spring_reference>
          <spring_stiffness>0</spring_stiffness>
        </dynamics>
        <use_parent_model_frame>1</use_parent_model_frame>
      </axis>
    </joint>



    <link name='motor_1'>
      <pose>0.35 -0.42 0.300 0 0 0</pose>  <!-- 右前电机 -->
      <inertial>
        <pose>0 0 0 0 0 0</pose>
        <mass>0.05</mass>
        <inertia>
          <ixx>0.0166704</ixx>
          <ixy>0</ixy>
          <ixz>0</ixz>
          <iyy>0.0166704</iyy>
          <iyz>0</iyz>
          <izz>0.0167604</izz>
        </inertia>
      </inertial>
      <collision name='motor_1_collision'>
        <pose>0 0 0 0 0 0</pose>
        <geometry>
          <cylinder>
            <length>0.035</length>
            <radius>0.02</radius>
          </cylinder>
        </geometry>
        <surface>
          <contact>
            <ode/>
          </contact>
          <friction>
            <ode/>
          </friction>
        </surface>
      </collision>
      <visual name='motor_1_visual'>
        <pose>0 0 0 0 0 0</pose>
        <geometry>
          <cylinder>
            <length>0.035</length>
            <radius>0.02</radius>
          </cylinder>
        </geometry>
        <material>
          <ambient>0.175 0.175 0.175 1.0</ambient>
          <diffuse>0.175 0.175 0.175 1.0</diffuse>
        </material>
      </visual>
      <gravity>1</gravity>
      <velocity_decay/>
      <self_collide>0</self_collide>
    </link>

    <joint name='motor_1_joint' type='revolute'>
      <child>motor_1</child>
      <parent>base_link</parent>
      <axis>
        <xyz>0 1 0</xyz>
        <limit>
          <lower>-0.785</lower>
          <upper>0.785</upper>
        </limit>
        <dynamics>
          <friction>1.0</friction>
          <spring_reference>0</spring_reference>
          <spring_stiffness>0</spring_stiffness>
        </dynamics>
        <use_parent_model_frame>1</use_parent_model_frame>
      </axis>
    </joint>

    <link name='rotor_1'>
      <pose>0.35 -0.42 0.325 0 0 0</pose>  <!-- 右前旋翼 -->
      <inertial>
        <pose>0 0 0 0 0 0</pose>
        <mass>0.005</mass>
        <inertia>
          <ixx>9.75e-07</ixx>
          <ixy>0</ixy>
          <ixz>0</ixz>
          <iyy>0.000166704</iyy>
          <iyz>0</iyz>
          <izz>0.000167604</izz>
        </inertia>
      </inertial>
      <collision name='rotor_1_collision'>
        <pose>0 0 0 0 0 0</pose>
        <geometry>
          <cylinder>
            <length>0.005</length>
            <radius>0.1</radius>
          </cylinder>
        </geometry>
        <surface>
          <contact>
            <ode/>
          </contact>
          <friction>
            <ode/>
          </friction>
        </surface>
      </collision>
      <visual name='rotor_1_visual'>
        <pose>0 0 0 0 0 0</pose>
        <geometry>
          <mesh>
            <scale>1 1 1</scale>
            <uri>model://standard_vtol/meshes/iris_prop_cw.dae</uri>
          </mesh>
        </geometry>
        <material> <!-- DarkGrey-->
          <ambient>0.175 0.175 0.175 1.0</ambient>
          <diffuse>0.175 0.175 0.175 1.0</diffuse>
        </material>
      </visual>
      <gravity>1</gravity>
      <velocity_decay/>
      <self_collide>0</self_collide>
    </link>
    <joint name='rotor_1_joint' type='revolute'>
      <child>rotor_1</child>
      <parent>motor_1</parent>
      <axis>
        <xyz>0 0 1</xyz>
        <limit>
          <lower>-1e+16</lower>
          <upper>1e+16</upper>
        </limit>
        <dynamics>
          <spring_reference>0</spring_reference>
          <spring_stiffness>0</spring_stiffness>
        </dynamics>
        <use_parent_model_frame>1</use_parent_model_frame>
      </axis>
    </joint>

    <!-- 后部可倾转电机 -->
    <link name='motor_2'>
      <pose>-1.08 0 0.1 0 0 0</pose>  <!-- 后部中央位置 -->
      <inertial>
        <pose>0 0 0 0 0 0</pose>
        <mass>0.05</mass>
        <inertia>
          <ixx>0.0166704</ixx>
          <ixy>0</ixy>
          <ixz>0</ixz>
          <iyy>0.0166704</iyy>
          <iyz>0</iyz>
          <izz>0.0167604</izz>
        </inertia>
      </inertial>
      <collision name='motor_2_collision'>
        <pose>0 0 0 0 0 0</pose>
        <geometry>
          <cylinder>
            <length>0.035</length>
            <radius>0.02</radius>
          </cylinder>
        </geometry>
        <surface>
          <contact>
            <ode/>
          </contact>
          <friction>
            <ode/>
          </friction>
        </surface>
      </collision>
      <visual name='motor_2_visual'>
        <pose>0 0 0 0 0 0</pose>
        <geometry>
          <cylinder>
            <length>0.035</length>
            <radius>0.02</radius>
          </cylinder>
        </geometry>
        <material>
          <ambient>0.175 0.175 0.175 1.0</ambient>
          <diffuse>0.175 0.175 0.175 1.0</diffuse>
        </material>
      </visual>
      <gravity>1</gravity>
      <velocity_decay/>
      <self_collide>0</self_collide>
    </link>

    <!-- 后部旋翼 -->
    <link name='rotor_2'>
      <pose>-1.08 0 0.075 0 0 0</pose>  <!-- 电机上方25mm -->
      <inertial>
        <pose>0 0 0 0 0 0</pose>
        <mass>0.005</mass>
        <inertia>
          <ixx>9.75e-07</ixx>
          <ixy>0</ixy>
          <ixz>0</ixz>
          <iyy>0.000166704</iyy>
          <iyz>0</iyz>
          <izz>0.000167604</izz>
        </inertia>
      </inertial>
      <collision name='rotor_2_collision'>
        <pose>0 0 0 0 0 0</pose>
        <geometry>
          <cylinder>
            <length>0.005</length>
            <radius>0.1</radius>
          </cylinder>
        </geometry>
        <surface>
          <contact>
            <ode/>
          </contact>
          <friction>
            <ode/>
          </friction>
        </surface>
      </collision>
      <visual name='rotor_2_visual'>
        <pose>0 0 0 0 0 0</pose>
        <geometry>
          <mesh>
            <scale>1 1 1</scale>
            <uri>model://standard_vtol/meshes/iris_prop_ccw.dae</uri>
          </mesh>
        </geometry>
        <material>  <!-- Blue -->
          <ambient>0 0 1 1.0</ambient>
          <diffuse>0 0 1 1.0</diffuse>
        </material>
      </visual>
      <gravity>1</gravity>
      <velocity_decay/>
      <self_collide>0</self_collide>
    </link>
    <!-- 后部电机倾转关节 -->
    <joint name='motor_2_joint' type='revolute'>
      <child>motor_2</child>
      <parent>base_link</parent>
      <axis>
        <xyz>0 1 0</xyz>
        <limit>
          <lower>-0.785</lower>
          <upper>0.785</upper>
        </limit>
        <dynamics>
          <friction>1.0</friction>
          <spring_reference>0</spring_reference>
          <spring_stiffness>0</spring_stiffness>
        </dynamics>
        <use_parent_model_frame>1</use_parent_model_frame>
      </axis>
    </joint>

    <!-- 后部旋翼旋转关节 -->
    <joint name='rotor_2_joint' type='revolute'>
      <child>rotor_2</child>
      <parent>motor_2</parent>
      <axis>
        <xyz>0 0 1</xyz>
        <limit>
          <lower>-1e+16</lower>
          <upper>1e+16</upper>
        </limit>
        <dynamics>
          <spring_reference>0</spring_reference>
          <spring_stiffness>0</spring_stiffness>
        </dynamics>
        <use_parent_model_frame>1</use_parent_model_frame>
      </axis>
    </joint>
    <!-- 后部电机倾转控制 -->
    <plugin
      filename="gz-sim-joint-position-controller-system" name="gz::sim::systems::JointPositionController">
      <joint_name>motor_2_joint</joint_name>
      <sub_topic>servo_2</sub_topic>
      <p_gain>100</p_gain>
      <i_gain>0</i_gain>
      <d_gain>0</d_gain>
      <i_max>0.0</i_max>
      <i_min>0.0</i_min>
      <cmd_max>2</cmd_max>
      <cmd_min>-2</cmd_min>
      <err_max>0.2</err_max>
    </plugin>

    <!-- 后部旋翼电机控制 -->
    <plugin filename="gz-sim-multicopter-motor-model-system" name="gz::sim::systems::MulticopterMotorModel">
      <jointName>rotor_2_joint</jointName>
      <linkName>rotor_2</linkName>
      <turningDirection>ccw</turningDirection>
      <timeConstantUp>0.0125</timeConstantUp>
      <timeConstantDown>0.025</timeConstantDown>
      <maxRotVelocity>1500</maxRotVelocity>
      <motorConstant>2e-05</motorConstant>
      <momentConstant>0.06</momentConstant>
      <commandSubTopic>command/motor_speed</commandSubTopic>
      <motorNumber>2</motorNumber>
      <rotorDragCoefficient>0.0000806428</rotorDragCoefficient>
      <rollingMomentCoefficient>1e-06</rollingMomentCoefficient>
      <rotorVelocitySlowdownSim>20</rotorVelocitySlowdownSim>
      <motorType>velocity</motorType>
    </plugin>
    <plugin filename="gz-sim-multicopter-motor-model-system" name="gz::sim::systems::MulticopterMotorModel">
      <jointName>rotor_0_joint</jointName>
      <linkName>rotor_0</linkName>
      <turningDirection>ccw</turningDirection>
      <timeConstantUp>0.0125</timeConstantUp>
      <timeConstantDown>0.025</timeConstantDown>
      <maxRotVelocity>1500</maxRotVelocity>
      <motorConstant>2e-05</motorConstant>
      <momentConstant>0.06</momentConstant>
      <commandSubTopic>command/motor_speed</commandSubTopic>
      <motorNumber>0</motorNumber>
      <rotorDragCoefficient>0.0000806428</rotorDragCoefficient>
      <rollingMomentCoefficient>1e-06</rollingMomentCoefficient>
      <rotorVelocitySlowdownSim>20</rotorVelocitySlowdownSim>
      <motorType>velocity</motorType>
    </plugin>
    <plugin
      filename="gz-sim-joint-position-controller-system" name="gz::sim::systems::JointPositionController">
      <joint_name>motor_0_joint</joint_name>
      <sub_topic>servo_0</sub_topic>
      <p_gain>100</p_gain>
      <i_gain>0</i_gain>
      <d_gain>0</d_gain>
      <i_max>0.0</i_max>
      <i_min>0.0</i_min>
      <cmd_max>2</cmd_max>
      <cmd_min>-2</cmd_min>
      <err_max>0.2</err_max>
    </plugin>
    <plugin filename="gz-sim-multicopter-motor-model-system" name="gz::sim::systems::MulticopterMotorModel">
      <jointName>rotor_1_joint</jointName>
      <linkName>rotor_1</linkName>
      <turningDirection>cw</turningDirection>
      <timeConstantUp>0.0125</timeConstantUp>
      <timeConstantDown>0.025</timeConstantDown>
      <maxRotVelocity>1500</maxRotVelocity>
      <motorConstant>2e-05</motorConstant>
      <momentConstant>0.06</momentConstant>
      <commandSubTopic>command/motor_speed</commandSubTopic>
      <motorNumber>1</motorNumber>
      <rotorDragCoefficient>0.0000806428</rotorDragCoefficient>
      <rollingMomentCoefficient>1e-06</rollingMomentCoefficient>
      <rotorVelocitySlowdownSim>20</rotorVelocitySlowdownSim>
      <motorType>velocity</motorType>
    </plugin>
    <plugin
      filename="gz-sim-joint-position-controller-system" name="gz::sim::systems::JointPositionController">
      <joint_name>motor_1_joint</joint_name>
      <sub_topic>servo_1</sub_topic>
      <p_gain>100</p_gain>
      <i_gain>0</i_gain>
      <d_gain>0</d_gain>
      <i_max>0.0</i_max>
      <i_min>0.0</i_min>
      <cmd_max>2</cmd_max>
      <cmd_min>-2</cmd_min>
      <err_max>0.2</err_max>
    </plugin>

    <plugin filename="gz-sim-advanced-lift-drag-system" name="gz::sim::systems::AdvancedLiftDrag">
      <a0>0.0</a0>
      <CL0>0.15188</CL0>
      <AR>8.5</AR>
      <eff>0.97</eff>
      <CLa>5.015</CLa>
      <cda>1.5</cda>
      <CD0>0.15</CD0>
      <Cem0>0.075</Cem0>
      <Cema>-0.463966</Cema>
      <CYb>-0.258244</CYb>
      <Cellb>-0.039250</Cellb>
      <Cenb>0.100826</Cenb>
      <CDp>0.0</CDp>
      <CYp>0.065861</CYp>
      <CLp>0.0</CLp>
      <Cellp>-0.487407</Cellp>
      <Cemp>0.0</Cemp>
      <Cenp>-0.040416</Cenp>
      <CDq>0.055166</CDq>
      <CYq>0.0</CYq>
      <CLq>7.971792</CLq>
      <Cellq>0.0</Cellq>
      <Cemq>-12.140140</Cemq>
      <Cenq>0.0</Cenq>
      <CDr>0.0</CDr>
      <CYr>0.230299</CYr>
      <CLr>0.0</CLr>
      <Cellr>0.078165</Cellr>
      <Cemr>0.0</Cemr>
      <Cenr>-0.089947</Cenr>
      <alpha_stall>0.3391428111</alpha_stall>
      <CLa_stall>-3.85</CLa_stall>
      <CDa_stall>-0.9233984055</CDa_stall>
      <Cema_stall>0</Cema_stall>
      <ref_pt>-0.12 0.0 0.0</ref_pt>
      <area>0.5</area>
      <mac>0.22</mac>
      <air_density>1.2041</air_density>
      <forward>1 0 0</forward>
      <upward>0 0 1</upward>
      <link_name>base_link</link_name>
      <num_ctrl_surfaces>0</num_ctrl_surfaces>
    </plugin>
    <static>0</static>
  </model>
</sdf>
